Workbook

Sheet LOOKUPS
A1: Lead Source | B1: Lead Owner | C1: Lead Status | D1: Crop Type | E1: Crop Condition | F1: Irrigation Type | G1: Visit Outcome | H1: Quatation Status | I1: Payment Status | J1: Districts (Karnataka) | K1: Field Visit Status | L1: Visited By | M1: Quatation Prepared by
A2: Advertisement | B2: Likitha V J | C2: Active | D2: Arecanut | E2: Healthy | F2: Drip | G2: Good Fit - Interested | H2: Draft | I2: Pending | J2: Bengaluru Urban | K2: Scheduled | L2: Dr. Manjunath | M2: Keerthi M J
A3: Social Media | B3: Abhijith | C3: Inactive | D3: Coconut | E3: Yellowing | F3: Sprinkler | G3: Need Follow-up | H3: Sent | I3: Advance Paid | J3: Bengaluru Rural | K3: Visited | L3: Keerthi M J | M3: Gowthami
A4: Walk-in | B4: Asmath Pasha | D4: Rubber | E4: Infestation | F4: Flood | G4: Not Interested | H4: In Discussion | I4: Partial | J4: Mysuru | M4: Likitha V J
A5: Referral | B5: Gowthami | D5: Coffee | E5: Disease | F5: Rainfed | G5: Needs More Info | H5: Accepted | I5: Received | J5: Mandya
A6: Telecaller | B6: Keerthi M J | D6: Pepper | E6: Poor Growth | F6: Mixed | G6: Price Concern | H6: Order dispatched | J6: Hassan
A7: Field Employee | B7: Nayana | D7: Cardamom | E7: Nutrient Deficiency | G7: Will Decide Later | H7: Order Delivered | J7: Tumkur
A8: Krushimela | B8: Annaiah K E | D8: Banana | H8: Rejected | J8: Chitradurga
D9: Paddy | J9: Davanagere
D10: Vegetables | J10: Shivamogga
D11: Other | J11: Chikmagalur
J12: Udupi
J13: Dakshina Kannada
J14: Uttara Kannada
J15: Belagavi
J16: Dharwad
J17: Haveri
J18: Gadag
J19: Bagalkot
J20: Vijayapura
J21: Kalaburagi
J22: Bidar
J23: Raichur
... J34: Manglore

Sheet LEADS
A1: Lead ID | B1: Created Date | C1: Lead Owner | D1: Source | E1: Farmer Name | F1: Phone | G1: Alt Phone | H1: WhatsApp | I1: Village | J1: Taluk | K1: District | L1: Farm Size (acres) | M1: Crop Type | N1: Crop Age | O1: No. Of Plants | P1: Irrigation Type | Q1: Initial Notes | R1: Lead Status | S1: Last Updated
A2: =IF(E2<>"", "LEA-"&TEXT(ROW()-1, "0000"), "") -> LEA-0001 | B2: 45956 | C2: Keerthi M J | D2: Referral | E2: Natesh | F2: 7483510354 | I2: Kalyani Agrahara | J2: thirthahalli | K2: Shivamogga | L2: 10 | M2: Arecanut | O2: 6600 | P2: Sprinkler | R2: Active | S2: =IF(E2<>"",TODAY(),"") -> 46039
A3: =IF(E3<>"", "LEA-"&TEXT(ROW()-1, "0000"), "") -> LEA-0002 | B3: 45932 | C3: Keerthi M J | D3: Referral | E3: Asha Rani | F3: 9620945945 | I3: Kugulur | J3: Davanagere | K3: Davanagere | L3: 7 | M3: Arecanut | O3: 3800 | P3: Drip | R3: Active | S3: =IF(E3<>"",TODAY(),"") -> 46039
A4: =IF(E4<>"", "LEA-"&TEXT(ROW()-1, "0000"), "") -> LEA-0003 | B4: 45924 | C4: Gowthami | D4: Social Media | E4: Dr Srinivas | F4: 9448245065 | G4: 8660163616 | I4: Kusarige | J4: Koppa | K4: Chikmagalur | L4: 5 | M4: Arecanut | N4: 6 | O4: 2400 | P4: Drip | R4: Active | S4: =IF(E4<>"",TODAY(),"") -> 46039
A5: =IF(E5<>"", "LEA-"&TEXT(ROW()-1, "0000"), "") -> LEA-0004 | B5: 45956 | C5: Keerthi M J | D5: Social Media | E5: Imran Syed Chand | F5: 9845526274 | G5: 9342745626 | H5: 9980341933 | I5: Hal Lakkavalli | J5: Shivamogga | K5: Shivamogga | L5: 18 | M5: Arecanut | N5: 20 | O5: 9000 | P5: Sprinkler | R5: Active | S5: =IF(E5<>"",TODAY(),"") -> 46039
A6: =IF(E6<>"", "LEA-"&TEXT(ROW()-1, "0000"), "") -> LEA-0005 | B6: 45955 | C6: Asmath Pasha | D6: Field Employee | E6: Syed Basha | F6: 9731159508 | I6: K K Mugge | J6: Bhadravathi | K6: Shivamogga | L6: 1.5 | M6: Arecanut | N6: 5 | O6: 800 | P6: Flood | R6: Active | S6: =IF(E6<>"",TODAY(),"") -> 46039
A7: =IF(E7<>"", "LEA-"&TEXT(ROW()-1, "0000"), "") -> LEA-0006 | B7: 45955 | C7: Asmath Pasha | D7: Field Employee | E7: Raghu | F7: 6362825605 | I7: Mullukere | J7: Bhadravathi | K7: Shivamogga | L7: 26 | M7: Arecanut | N7: 15 | O7: 13000 | P7: Flood | R7: Active | S7: =IF(E7<>"",TODAY(),"") -> 46039
A8: =IF(E8<>"", "LEA-"&TEXT(ROW()-1, "0000"), "") -> LEA-0007 | B8: 45955 | C8: Asmath Pasha | D8: Field Employee | E8: Naveen | F8: 8748905780 | I8: Mullukere | J8: Bhadravathi | K8: Shivamogga | L8: 1.5 | M8: Arecanut | N8: 25 | O8: 800 | P8: Flood | R8: Active | S8: =IF(E8<>"",TODAY(),"") -> 46039
A9: =IF(E9<>"", "LEA-"&TEXT(ROW()-1, "0000"), "") -> LEA-0008 | B9: 45955 | C9: Asmath Pasha | D9: Field Employee | E9: Jabbar Saad | F9: 9663715896 | I9: Sitarampura | J9: Bhadravathi | K9: Shivamogga | L9: 1.5 | M9: Arecanut | N9: 23 | O9: 800 | P9: Flood | R9: Active | S9: =IF(E9<>"",TODAY(),"") -> 46039
A10: =IF(E10<>"", "LEA-"&TEXT(ROW()-1, "0000"), "") -> LEA-0009 | B10: 45955 | C10: Asmath Pasha | D10: Field Employee | E10: Jagadeesh | F10: 9448207995 | I10: Kuddli | J10: Shivamogga | K10: Shivamogga | L10: 4 | M10: Arecanut | N10: 4 | O10: 2000 | P10: Flood | R10: Active | S10: =IF(E10<>"",TODAY(),"") -> 46039
A11: =IF(E11<>"", "LEA-"&TEXT(ROW()-1, "0000"), "") -> LEA-0010 | B11: 45955 | C11: Asmath Pasha | D11: Field Employee | E11: Abdul Masjuad | F11: 9980505837 | I11: Kuddli | J11: Shivamogga | K11: Shivamogga | L11: 4 | M11: Arecanut | N11: 4 | O11: 2000 | P11: Flood | R11: Active | S11: =IF(E11<>"",TODAY(),"") -> 46039
A12: =IF(E12<>"", "LEA-"&TEXT(ROW()-1, "0000"), "") -> LEA-0011 | B12: 45957 | C12: Asmath Pasha | D12: Field Employee | E12: Jaradhan | F12: 8549953806 | I12: Kuddli | J12: Shivamogga | K12: Shivamogga | L12: 16 | M12: Arecanut | N12: 20 | O12: 8000 | P12: Sprinkler | R12: Active | S12: =IF(E12<>"",TODAY(),"") -> 46039
A13: =IF(E13<>"", "LEA-"&TEXT(ROW()-1, "0000"), "") -> LEA-0012 | B13: 45972 | C13: Nayana | D13: Telecaller | E13: Krishna Murty | F13: 7760472319 | I13: Anavatti | J13: Holalkere | K13: Chitradurga | L13: 20 | M13: Arecanut | N13: 10 | O13: 10000 | P13: Drip | R13: Active | S13: =IF(E13<>"",TODAY(),"") -> 46039
A14: =IF(E14<>"", "LEA-"&TEXT(ROW()-1, "0000"), "") -> LEA-0013 | B14: 45972 | C14: Asmath Pasha | D14: Field Employee | E14: Ramesh | F14: 9743165075 | I14: Belguni | J14: Aynur | K14: Shivamogga | L14: 2.1 | M14: Arecanut | N14: 20 | O14: 1300 | R14: Active | S14: =IF(E14<>"",TODAY(),"") -> 46039
A15: =IF(E15<>"", "LEA-"&TEXT(ROW()-1, "0000"), "") -> LEA-0014 | B15: 45972 | C15: Asmath Pasha | D15: Field Employee | E15: Govinda raj | F15: 7760472319 | I15: Belguni | J15: Aynur | K15: Shivamogga | L15: 2 | M15: Arecanut | N15: 6 | O15: 1200 | R15: Active | S15: =IF(E15<>"",TODAY(),"") -> 46039
A16: =IF(E16<>"", "LEA-"&TEXT(ROW()-1, "0000"), "") -> LEA-0015 | B16: 45972 | C16: Asmath Pasha | D16: Field Employee | E16: Manjogi Rao | F16: 9980317624 | I16: Belguni | J16: Aynur | K16: Shivamogga | L16: 5.6 | M16: Arecanut | N16: 10 | O16: 3400 | R16: Active | S16: =IF(E16<>"",TODAY(),"") -> 46039
A17: =IF(E17<>"", "LEA-"&TEXT(ROW()-1, "0000"), "") -> LEA-0016 | B17: 45972 | C17: Asmath Pasha | D17: Field Employee | E17: Maheshwrappa | F17: 9980592441 | I17: Thammadihalli | J17: Aynur | K17: Shivamogga | L17: 1 | M17: Arecanut | N17: 2 | O17: 600 | R17: Active | S17: =IF(E17<>"",TODAY(),"") -> 46039
A18: =IF(E18<>"", "LEA-"&TEXT(ROW()-1, "0000"), "") -> LEA-0017 | B18: 45972 | C18: Asmath Pasha | D18: Field Employee | E18: Swamy Rao | F18: 8660863701 | I18: Kalkoppa | J18: Thirthahalli | K18: Shivamogga | L18: 5 | M18: Arecanut | N18: 18 | O18: 3000 | R18: Active | S18: =IF(E18<>"",TODAY(),"") -> 46039
A19: =IF(E19<>"", "LEA-"&TEXT(ROW()-1, "0000"), "") -> LEA-0018 | B19: 45973 | C19: Nayana | D19: Walk-in | E19: Prahaladh | F19: 9448202287 | I19: Kodihalli | J19: Kadur | K19: Chikmagalur | L19: 8 | M19: Arecanut | N19: 15 | O19: 3000 | P19: Drip | R19: Active | S19: =IF(E19<>"",TODAY(),"") -> 46039
A20: =IF(E20<>"", "LEA-"&TEXT(ROW()-1, "0000"), "") -> LEA-0019 | B20: 45978 | C20: Keerthi M J | D20: Referral | E20: Shabeer | F20: 7019466482 | H20: 9449623265 | I20: Naluru | J20: Thirthahalli | K20: Shivamogga | L20: 6 | M20: Arecanut | N20: 25 | O20: 3000 | P20: Sprinkler | R20: Active | S20: =IF(E20<>"",TODAY(),"") -> 46039
A21: =IF(E21<>"", "LEA-"&TEXT(ROW()-1, "0000"), "") -> LEA-0020 | B21: 45978 | C21: Keerthi M J | D21: Referral | E21: Mahaballesh | F21: 9481950215 | H21: 7760675722 | I21: Hasirumane | J21: Thirthahalli | K21: Shivamogga | L21: 2 | M21: Arecanut | N21: 25 | O21: 1200 | P21: Sprinkler | R21: Active | S21: =IF(E21<>"",TODAY(),"") -> 46039
A22: =IF(E22<>"", "LEA-"&TEXT(ROW()-1, "0000"), "") -> LEA-0021 | B22: 45978 | C22: Keerthi M J | D22: Referral | E22: Girish | F22: 9480354283 | I22: Savitrimane | J22: Thirthahalli | K22: Shivamogga | L22: 1 | M22: Arecanut | N22: 25 | O22: 400 | P22: Sprinkler | R22: Active | S22: =IF(E22<>"",TODAY(),"") -> 46039
A23: =IF(E23<>"", "LEA-"&TEXT(ROW()-1, "0000"), "") -> LEA-0022 | B23: 45978 | C23: Keerthi M J | D23: Referral | E23: Siddappa K.C | F23: 9480505938 | I23: Kanchinalu | J23: Thirthahalli | K23: Shivamogga | L23: 1 | M23: Arecanut | N23: 10 | O23: 400 | P23: Sprinkler | R23: Active | S23: =IF(E23<>"",TODAY(),"") -> 46039
A24: =IF(E24<>"", "LEA-"&TEXT(ROW()-1, "0000"), "") -> LEA-0023 | B24: 45978 | C24: Keerthi M J | D24: Referral | E24: Ashiq | F24: 7899154604 | H24: 9482403665 | I24: Neralakoduge | J24: Thirthahalli | K24: Shivamogga | L24: 1 | M24: Arecanut | N24: 20 | O24: 400 | P24: Sprinkler | R24: Active | S24: =IF(E24<>"",TODAY(),"") -> 46039
A25: =IF(E25<>"", "LEA-"&TEXT(ROW()-1, "0000"), "") -> LEA-0024 | B25: 45978 | C25: Keerthi M J | D25: Referral | E25: Rabort | F25: 9449390925 | I25: Kalyani Agrahara | J25: Thirthahalli | K25: Shivamogga | L25: 8 | M25: Arecanut | N25: 25 | O25: 4000 | P25: Sprinkler | R25: Active | S25: =IF(E25<>"",TODAY(),"") -> 46039
A26: =IF(E26<>"", "LEA-"&TEXT(ROW()-1, "0000"), "") -> LEA-0025 | B26: 45980 | C26: Asmath Pasha | D26: Field Employee | E26: Sunil kumar | F26: 7975242855 | I26: Rameshwar | J26: Savlanga | K26: Shivamogga | L26: 1.8 | M26: Arecanut | N26: 18 | O26: 1080 | R26: Active | S26: =IF(E26<>"",TODAY(),"") -> 46039
A27: =IF(E27<>"", "LEA-"&TEXT(ROW()-1, "0000"), "") -> LEA-0026 | B27: 45980 | C27: Asmath Pasha | D27: Field Employee | E27: Kumar Swamy | F27: 9986771949 | I27: Sogilu | J27: Savlanga | K27: Shivamogga | L27: 3 | M27: Arecanut | N27: 18 | O27: 1800 | R27: Active | S27: =IF(E27<>"",TODAY(),"") -> 46039
A28: =IF(E28<>"", "LEA-"&TEXT(ROW()-1, "0000"), "") -> LEA-0027 | B28: 45980 | C28: Asmath Pasha | D28: Field Employee | E28: Nagaraj H | F28: 8792444217 | I28: Rameshwar | J28: Savlanga | K28: Shivamogga | L28: 0.75 | M28: Arecanut | N28: 6 | O28: 450 | R28: Active | S28: =IF(E28<>"",TODAY(),"") -> 46039
A29: =IF(E29<>"", "LEA-"&TEXT(ROW()-1, "0000"), "") -> LEA-0028 | B29: 45980 | C29: Asmath Pasha | D29: Field Employee | E29: Mahesh | F29: 9986457008 | I29: Bikanahalli | J29: Savlanga | K29: Shivamogga | L29: 8.3 | M29: Arecanut | N29: 15 | O29: 5000 | R29: Active | S29: =IF(E29<>"",TODAY(),"") -> 46039
A30: =IF(E30<>"", "LEA-"&TEXT(ROW()-1, "0000"), "") -> LEA-0029 | B30: 45980 | C30: Asmath Pasha | D30: Field Employee | E30: Jeevan | F30: 7996709365 | I30: Sogilu | J30: Savlanga | K30: Shivamogga | L30: 2 | M30: Arecanut | N30: 13 | O30: 1200 | R30: Active | S30: =IF(E30<>"",TODAY(),"") -> 46039
A31: =IF(E31<>"", "LEA-"&TEXT(ROW()-1, "0000"), "") -> LEA-0030 | B31: 45980 | C31: Asmath Pasha | D31: Field Employee | E31: Chetan | F31: 8139986425 | I31: Sogilu | J31: Savlanga | K31: Shivamogga | L31: 2 | M31: Arecanut | N31: 13 | O31: 1200 | R31: Active | S31: =IF(E31<>"",TODAY(),"") -> 46039
A32: =IF(E32<>"", "LEA-"&TEXT(ROW()-1, "0000"), "") -> LEA-0031 | B32: 45980 | C32: Asmath Pasha | D32: Field Employee | E32: Gurumurthy | F32: 9986904545 | I32: Sogilu | J32: Savlanga | K32: Shivamogga | L32: 2 | M32: Arecanut | N32: 3 | O32: 1200 | R32: Active | S32: =IF(E32<>"",TODAY(),"") -> 46039
A33: =IF(E33<>"", "LEA-"&TEXT(ROW()-1, "0000"), "") -> LEA-0032 | B33: 45980 | C33: Asmath Pasha | D33: Field Employee | E33: Maheshwar | F33: 9945814519 | I33: Sogilu | J33: Savlanga | K33: Shivamogga | L33: 4.16 | M33: Arecanut | N33: 25 | O33: 2500 | R33: Active | S33: =IF(E33<>"",TODAY(),"") -> 46039
A34: =IF(E34<>"", "LEA-"&TEXT(ROW()-1, "0000"), "") -> LEA-0033 | B34: 45980 | C34: Asmath Pasha | D34: Field Employee | E34: Rajappa | F34: 9739248845 | I34: Sogilu | J34: Savlanga | K34: Shivamogga | L34: 3 | M34: Arecanut | N34: 15,8 | O34: 1800 | R34: Active | S34: =IF(E34<>"",TODAY(),"") -> 46039
A35: =IF(E35<>"", "LEA-"&TEXT(ROW()-1, "0000"), "") -> LEA-0034 | B35: 45980 | C35: Asmath Pasha | D35: Field Employee | E35: Chandrashekar | F35: 884382218 | I35: Rameshwar | J35: Savlanga | K35: Shivamogga | L35: 2.1 | M35: Arecanut | N35: 14 | O35: 1260 | R35: Active | S35: =IF(E35<>"",TODAY(),"") -> 46039
A36: =IF(E36<>"", "LEA-"&TEXT(ROW()-1, "0000"), "") -> LEA-0035 | B36: 45981 | C36: Asmath Pasha | D36: Field Employee | E36: Neelkantappa | F36: 9986327688 | I36: Harnahalli | J36: Aynur | K36: Shivamogga | L36: 3 | M36: Arecanut | N36: 9 | O36: 1800 | R36: Active | S36: =IF(E36<>"",TODAY(),"") -> 46039
A37: =IF(E37<>"", "LEA-"&TEXT(ROW()-1, "0000"), "") -> LEA-0036 | B37: 45981 | C37: Asmath Pasha | D37: Field Employee | E37: Shivanna | F37: 9980517484 | I37: Harnahalli | J37: Aynur | K37: Shivamogga | L37: 1 | M37: Arecanut | N37: 9 | O37: 600 | R37: Active | S37: =IF(E37<>"",TODAY(),"") -> 46039
A38: =IF(E38<>"", "LEA-"&TEXT(ROW()-1, "0000"), "") -> LEA-0037 | B38: 45981 | C38: Asmath Pasha | D38: Field Employee | E38: Lokeshappa | F38: 9916635481 | I38: Harnahalli | J38: Aynur | K38: Shivamogga | L38: 1.5 | M38: Arecanut | N38: 20 | O38: 900 | R38: Active | S38: =IF(E38<>"",TODAY(),"") -> 46039
A39: =IF(E39<>"", "LEA-"&TEXT(ROW()-1, "0000"), "") -> LEA-0038 | B39: 45981 | C39: Asmath Pasha | D39: Field Employee | E39: V.P.Veerabhadrappa | F39: 9449103983 | I39: Harnahalli | J39: Aynur | K39: Shivamogga | L39: 1 | M39: Arecanut | N39: 15 | O39: 600 | R39: Active | S39: =IF(E39<>"",TODAY(),"") -> 46039
A40: =IF(E40<>"", "LEA-"&TEXT(ROW()-1, "0000"), "") -> LEA-0039 | B40: 45981 | C40: Asmath Pasha | D40: Field Employee | E40: Krishna Murty | F40: 9448189403 | I40: Sudoor | J40: Rippanpete | K40: Shivamogga | L40: 4 | M40: Arecanut | N40: 45802 | O40: 2400 | R40: Active | S40: =IF(E40<>"",TODAY(),"") -> 46039
...

Sheet FIELD VISITS
A1: Visit ID | B1: Lead ID | C1: Farmer Name | D1: Mobile Number | E1: Village | F1: Taluk | G1: Number of Plants | H1: Visit Scheduled Date | I1: Visit Actual Date | J1: Visited By | K1: Visit Outcome | L1: Visit Notes | M1: Diagnosis Report Sent for Quotation | N1: Next Follow-up Date | O1: Status
A2: =IF(B2<>"","FIE-"&TEXT(ROW()-1,"0000"),"") -> FIE-0001 | B2: LEA-0001 | C2: =IF(B2<>"",VLOOKUP(B2,LEADS!A:E,5,FALSE),"") -> Natesh | D2: =IF(B2<>"",VLOOKUP(B2,LEADS!A:F,6,FALSE),"") -> 7483510354 | E2: =IF(B2<>"",VLOOKUP(B2,LEADS!A:I,9,FALSE),"") -> Kalyani Agrahara | F2: =IF(B2<>"",VLOOKUP(B2,LEADS!A:J,10,FALSE),"") -> thirthahalli | G2: =IF(B2<>"",VLOOKUP(B2,LEADS!A:O,15,FALSE),"") -> 6600 | H2: 45956 | I2: 45963 | J2: Dr. Manjunath | K2: Good Fit - Interested | M2: Yes | O2: =IF(AND(ISBLANK(Field_Visit[Visit Actual Date]),NOT(ISBLANK(Field_Visit[Visit Scheduled Date]))),"Scheduled",IF(NOT(ISBLANK(Field_Visit[Visit Actual Date])),"Visited","")) -> Visited
A3: =IF(B3<>"","FIE-"&TEXT(ROW()-1,"0000"),"") -> FIE-0002 | B3: LEA-0003 | C3: =IF(B3<>"",VLOOKUP(B3,LEADS!A:E,5,FALSE),"") -> Dr Srinivas | D3: =IF(B3<>"",VLOOKUP(B3,LEADS!A:F,6,FALSE),"") -> 9448245065 | E3: =IF(B3<>"",VLOOKUP(B3,LEADS!A:I,9,FALSE),"") -> Kusarige | F3: =IF(B3<>"",VLOOKUP(B3,LEADS!A:J,10,FALSE),"") -> Koppa | G3: =IF(B3<>"",VLOOKUP(B3,LEADS!A:O,15,FALSE),"") -> 2400 | H3: 45924 | I3: 45924 | J3: Dr. Manjunath | K3: Good Fit - Interested | M3: Yes | N3: 45920 | O3: =IF(AND(ISBLANK(Field_Visit[Visit Actual Date]),NOT(ISBLANK(Field_Visit[Visit Scheduled Date]))),"Scheduled",IF(NOT(ISBLANK(Field_Visit[Visit Actual Date])),"Visited","")) -> Visited
A4: =IF(B4<>"","FIE-"&TEXT(ROW()-1,"0000"),"") -> FIE-0003 | B4: LEA-0002 | C4: =IF(B4<>"",VLOOKUP(B4,LEADS!A:E,5,FALSE),"") -> Asha Rani | D4: =IF(B4<>"",VLOOKUP(B4,LEADS!A:F,6,FALSE),"") -> 9620945945 | E4: =IF(B4<>"",VLOOKUP(B4,LEADS!A:I,9,FALSE),"") -> Kugulur | F4: =IF(B4<>"",VLOOKUP(B4,LEADS!A:J,10,FALSE),"") -> Davanagere | G4: =IF(B4<>"",VLOOKUP(B4,LEADS!A:O,15,FALSE),"") -> 3800 | H4: 45933 | I4: 45933 | J4: Dr. Manjunath | K4: Good Fit - Interested | M4: Yes | N4: 45957 | O4: =IF(AND(ISBLANK(Field_Visit[Visit Actual Date]),NOT(ISBLANK(Field_Visit[Visit Scheduled Date]))),"Scheduled",IF(NOT(ISBLANK(Field_Visit[Visit Actual Date])),"Visited","")) -> Visited
A5: =IF(B5<>"","FIE-"&TEXT(ROW()-1,"0000"),"") -> FIE-0004 | B5: LEA-0004 | C5: =IF(B5<>"",VLOOKUP(B5,LEADS!A:E,5,FALSE),"") -> Imran Syed Chand | D5: =IF(B5<>"",VLOOKUP(B5,LEADS!A:F,6,FALSE),"") -> 9845526274 | E5: =IF(B5<>"",VLOOKUP(B5,LEADS!A:I,9,FALSE),"") -> Hal Lakkavalli | F5: =IF(B5<>"",VLOOKUP(B5,LEADS!A:J,10,FALSE),"") -> Shivamogga | G5: =IF(B5<>"",VLOOKUP(B5,LEADS!A:O,15,FALSE),"") -> 9000 | H5: 45928 | I5: 45928 | J5: Dr. Manjunath | K5: Price Concern | M5: Yes | N5: 45929 | O5: =IF(AND(ISBLANK(Field_Visit[Visit Actual Date]),NOT(ISBLANK(Field_Visit[Visit Scheduled Date]))),"Scheduled",IF(NOT(ISBLANK(Field_Visit[Visit Actual Date])),"Visited","")) -> Visited
A6: =IF(B6<>"","FIE-"&TEXT(ROW()-1,"0000"),"") -> FIE-0005 | B6: LEA-0005 | C6: =IF(B6<>"",VLOOKUP(B6,LEADS!A:E,5,FALSE),"") -> Syed Basha | D6: =IF(B6<>"",VLOOKUP(B6,LEADS!A:F,6,FALSE),"") -> 9731159508 | E6: =IF(B6<>"",VLOOKUP(B6,LEADS!A:I,9,FALSE),"") -> K K Mugge | F6: =IF(B6<>"",VLOOKUP(B6,LEADS!A:J,10,FALSE),"") -> Bhadravathi | G6: =IF(B6<>"",VLOOKUP(B6,LEADS!A:O,15,FALSE),"") -> 800 | H6: 45957 | I6: 45957 | J6: Dr. Manjunath | K6: Need Follow-up | N6: 45958 | O6: =IF(AND(ISBLANK(Field_Visit[Visit Actual Date]),NOT(ISBLANK(Field_Visit[Visit Scheduled Date]))),"Scheduled",IF(NOT(ISBLANK(Field_Visit[Visit Actual Date])),"Visited","")) -> Visited
A7: =IF(B7<>"","FIE-"&TEXT(ROW()-1,"0000"),"") -> FIE-0006 | B7: LEA-0006 | C7: =IF(B7<>"",VLOOKUP(B7,LEADS!A:E,5,FALSE),"") -> Raghu | D7: =IF(B7<>"",VLOOKUP(B7,LEADS!A:F,6,FALSE),"") -> 6362825605 | E7: =IF(B7<>"",VLOOKUP(B7,LEADS!A:I,9,FALSE),"") -> Mullukere | F7: =IF(B7<>"",VLOOKUP(B7,LEADS!A:J,10,FALSE),"") -> Bhadravathi | G7: =IF(B7<>"",VLOOKUP(B7,LEADS!A:O,15,FALSE),"") -> 13000 | H7: 45957 | I7: 45957 | J7: Dr. Manjunath | K7: Need Follow-up | N7: 45958 | O7: =IF(AND(ISBLANK(Field_Visit[Visit Actual Date]),NOT(ISBLANK(Field_Visit[Visit Scheduled Date]))),"Scheduled",IF(NOT(ISBLANK(Field_Visit[Visit Actual Date])),"Visited","")) -> Visited
A8: =IF(B8<>"","FIE-"&TEXT(ROW()-1,"0000"),"") -> FIE-0007 | B8: LEA-0007 | C8: =IF(B8<>"",VLOOKUP(B8,LEADS!A:E,5,FALSE),"") -> Naveen | D8: =IF(B8<>"",VLOOKUP(B8,LEADS!A:F,6,FALSE),"") -> 8748905780 | E8: =IF(B8<>"",VLOOKUP(B8,LEADS!A:I,9,FALSE),"") -> Mullukere | F8: =IF(B8<>"",VLOOKUP(B8,LEADS!A:J,10,FALSE),"") -> Bhadravathi | G8: =IF(B8<>"",VLOOKUP(B8,LEADS!A:O,15,FALSE),"") -> 800 | H8: 45957 | I8: 45957 | J8: Dr. Manjunath | K8: Need Follow-up | N8: 45958 | O8: =IF(AND(ISBLANK(Field_Visit[Visit Actual Date]),NOT(ISBLANK(Field_Visit[Visit Scheduled Date]))),"Scheduled",IF(NOT(ISBLANK(Field_Visit[Visit Actual Date])),"Visited","")) -> Visited
A9: =IF(B9<>"","FIE-"&TEXT(ROW()-1,"0000"),"") -> FIE-0008 | B9: LEA-0008 | C9: =IF(B9<>"",VLOOKUP(B9,LEADS!A:E,5,FALSE),"") -> Jabbar Saad | D9: =IF(B9<>"",VLOOKUP(B9,LEADS!A:F,6,FALSE),"") -> 9663715896 | E9: =IF(B9<>"",VLOOKUP(B9,LEADS!A:I,9,FALSE),"") -> Sitarampura | F9: =IF(B9<>"",VLOOKUP(B9,LEADS!A:J,10,FALSE),"") -> Bhadravathi | G9: =IF(B9<>"",VLOOKUP(B9,LEADS!A:O,15,FALSE),"") -> 800 | H9: 45957 | I9: 45957 | J9: Dr. Manjunath | K9: Need Follow-up | N9: 45958 | O9: =IF(AND(ISBLANK(Field_Visit[Visit Actual Date]),NOT(ISBLANK(Field_Visit[Visit Scheduled Date]))),"Scheduled",IF(NOT(ISBLANK(Field_Visit[Visit Actual Date])),"Visited","")) -> Visited
A10: =IF(B10<>"","FIE-"&TEXT(ROW()-1,"0000"),"") -> FIE-0009 | B10: LEA-0009 | C10: =IF(B10<>"",VLOOKUP(B10,LEADS!A:E,5,FALSE),"") -> Jagadeesh | D10: =IF(B10<>"",VLOOKUP(B10,LEADS!A:F,6,FALSE),"") -> 9448207995 | E10: =IF(B10<>"",VLOOKUP(B10,LEADS!A:I,9,FALSE),"") -> Kuddli | F10: =IF(B10<>"",VLOOKUP(B10,LEADS!A:J,10,FALSE),"") -> Shivamogga | G10: =IF(B10<>"",VLOOKUP(B10,LEADS!A:O,15,FALSE),"") -> 2000 | H10: 45957 | I10: 45957 | J10: Dr. Manjunath | K10: Need Follow-up | N10: 45958 | O10: =IF(AND(ISBLANK(Field_Visit[Visit Actual Date]),NOT(ISBLANK(Field_Visit[Visit Scheduled Date]))),"Scheduled",IF(NOT(ISBLANK(Field_Visit[Visit Actual Date])),"Visited","")) -> Visited
A11: =IF(B11<>"","FIE-"&TEXT(ROW()-1,"0000"),"") -> FIE-0010 | B11: LEA-0010 | C11: =IF(B11<>"",VLOOKUP(B11,LEADS!A:E,5,FALSE),"") -> Abdul Masjuad | D11: =IF(B11<>"",VLOOKUP(B11,LEADS!A:F,6,FALSE),"") -> 9980505837 | E11: =IF(B11<>"",VLOOKUP(B11,LEADS!A:I,9,FALSE),"") -> Kuddli | F11: =IF(B11<>"",VLOOKUP(B11,LEADS!A:J,10,FALSE),"") -> Shivamogga | G11: =IF(B11<>"",VLOOKUP(B11,LEADS!A:O,15,FALSE),"") -> 2000 | H11: 45957 | I11: 45957 | J11: Dr. Manjunath | K11: Need Follow-up | N11: 45958 | O11: =IF(AND(ISBLANK(Field_Visit[Visit Actual Date]),NOT(ISBLANK(Field_Visit[Visit Scheduled Date]))),"Scheduled",IF(NOT(ISBLANK(Field_Visit[Visit Actual Date])),"Visited","")) -> Visited
A12: =IF(B12<>"","FIE-"&TEXT(ROW()-1,"0000"),"") -> FIE-0011 | B12: LEA-0011 | C12: =IF(B12<>"",VLOOKUP(B12,LEADS!A:E,5,FALSE),"") -> Jaradhan | D12: =IF(B12<>"",VLOOKUP(B12,LEADS!A:F,6,FALSE),"") -> 8549953806 | E12: =IF(B12<>"",VLOOKUP(B12,LEADS!A:I,9,FALSE),"") -> Kuddli | F12: =IF(B12<>"",VLOOKUP(B12,LEADS!A:J,10,FALSE),"") -> Shivamogga | G12: =IF(B12<>"",VLOOKUP(B12,LEADS!A:O,15,FALSE),"") -> 8000 | H12: 45957 | I12: 45957 | J12: Dr. Manjunath | K12: Need Follow-up | N12: 45958 | O12: =IF(AND(ISBLANK(Field_Visit[Visit Actual Date]),NOT(ISBLANK(Field_Visit[Visit Scheduled Date]))),"Scheduled",IF(NOT(ISBLANK(Field_Visit[Visit Actual Date])),"Visited","")) -> Visited
A13: =IF(B13<>"","FIE-"&TEXT(ROW()-1,"0000"),"") -> FIE-0012 | B13: LEA-0012 | C13: =IF(B13<>"",VLOOKUP(B13,LEADS!A:E,5,FALSE),"") -> Krishna Murty | D13: =IF(B13<>"",VLOOKUP(B13,LEADS!A:F,6,FALSE),"") -> 7760472319 | E13: =IF(B13<>"",VLOOKUP(B13,LEADS!A:I,9,FALSE),"") -> Anavatti | F13: =IF(B13<>"",VLOOKUP(B13,LEADS!A:J,10,FALSE),"") -> Holalkere | G13: =IF(B13<>"",VLOOKUP(B13,LEADS!A:O,15,FALSE),"") -> 10000 | H13: 45974 | J13: Dr. Manjunath | O13: =IF(AND(ISBLANK(Field_Visit[Visit Actual Date]),NOT(ISBLANK(Field_Visit[Visit Scheduled Date]))),"Scheduled",IF(NOT(ISBLANK(Field_Visit[Visit Actual Date])),"Visited","")) -> Scheduled
A14: =IF(B14<>"","FIE-"&TEXT(ROW()-1,"0000"),"") -> FIE-0013 | B14: LEA-0018 | C14: =IF(B14<>"",VLOOKUP(B14,LEADS!A:E,5,FALSE),"") -> Prahaladh | D14: =IF(B14<>"",VLOOKUP(B14,LEADS!A:F,6,FALSE),"") -> 9448202287 | E14: =IF(B14<>"",VLOOKUP(B14,LEADS!A:I,9,FALSE),"") -> Kodihalli | F14: =IF(B14<>"",VLOOKUP(B14,LEADS!A:J,10,FALSE),"") -> Kadur | G14: =IF(B14<>"",VLOOKUP(B14,LEADS!A:O,15,FALSE),"") -> 3000 | H14: 45974 | J14: Dr. Manjunath | O14: =IF(AND(ISBLANK(Field_Visit[Visit Actual Date]),NOT(ISBLANK(Field_Visit[Visit Scheduled Date]))),"Scheduled",IF(NOT(ISBLANK(Field_Visit[Visit Actual Date])),"Visited","")) -> Scheduled
A15: =IF(B15<>"","FIE-"&TEXT(ROW()-1,"0000"),"") -> FIE-0014 | B15: LEA-0019 | C15: =IF(B15<>"",VLOOKUP(B15,LEADS!A:E,5,FALSE),"") -> Shabeer | D15: =IF(B15<>"",VLOOKUP(B15,LEADS!A:F,6,FALSE),"") -> 7019466482 | E15: =IF(B15<>"",VLOOKUP(B15,LEADS!A:I,9,FALSE),"") -> Naluru | F15: =IF(B15<>"",VLOOKUP(B15,LEADS!A:J,10,FALSE),"") -> Thirthahalli | G15: =IF(B15<>"",VLOOKUP(B15,LEADS!A:O,15,FALSE),"") -> 3000 | H15: 45979 | J15: Dr. Manjunath | O15: =IF(AND(ISBLANK(Field_Visit[Visit Actual Date]),NOT(ISBLANK(Field_Visit[Visit Scheduled Date]))),"Scheduled",IF(NOT(ISBLANK(Field_Visit[Visit Actual Date])),"Visited","")) -> Scheduled
A16: =IF(B16<>"","FIE-"&TEXT(ROW()-1,"0000"),"") -> FIE-0015 | B16: LEA-0020 | C16: =IF(B16<>"",VLOOKUP(B16,LEADS!A:E,5,FALSE),"") -> Mahaballesh | D16: =IF(B16<>"",VLOOKUP(B16,LEADS!A:F,6,FALSE),"") -> 9481950215 | E16: =IF(B16<>"",VLOOKUP(B16,LEADS!A:I,9,FALSE),"") -> Hasirumane | F16: =IF(B16<>"",VLOOKUP(B16,LEADS!A:J,10,FALSE),"") -> Thirthahalli | G16: =IF(B16<>"",VLOOKUP(B16,LEADS!A:O,15,FALSE),"") -> 1200 | H16: 45979 | J16: Dr. Manjunath | O16: =IF(AND(ISBLANK(Field_Visit[Visit Actual Date]),NOT(ISBLANK(Field_Visit[Visit Scheduled Date]))),"Scheduled",IF(NOT(ISBLANK(Field_Visit[Visit Actual Date])),"Visited","")) -> Scheduled
A17: =IF(B17<>"","FIE-"&TEXT(ROW()-1,"0000"),"") -> FIE-0016 | B17: LEA-0021 | C17: =IF(B17<>"",VLOOKUP(B17,LEADS!A:E,5,FALSE),"") -> Girish | D17: =IF(B17<>"",VLOOKUP(B17,LEADS!A:F,6,FALSE),"") -> 9480354283 | E17: =IF(B17<>"",VLOOKUP(B17,LEADS!A:I,9,FALSE),"") -> Savitrimane | F17: =IF(B17<>"",VLOOKUP(B17,LEADS!A:J,10,FALSE),"") -> Thirthahalli | G17: =IF(B17<>"",VLOOKUP(B17,LEADS!A:O,15,FALSE),"") -> 400 | H17: 45979 | J17: Dr. Manjunath | O17: =IF(AND(ISBLANK(Field_Visit[Visit Actual Date]),NOT(ISBLANK(Field_Visit[Visit Scheduled Date]))),"Scheduled",IF(NOT(ISBLANK(Field_Visit[Visit Actual Date])),"Visited","")) -> Scheduled
A18: =IF(B18<>"","FIE-"&TEXT(ROW()-1,"0000"),"") -> FIE-0017 | B18: LEA-0022 | C18: =IF(B18<>"",VLOOKUP(B18,LEADS!A:E,5,FALSE),"") -> Siddappa K.C | D18: =IF(B18<>"",VLOOKUP(B18,LEADS!A:F,6,FALSE),"") -> 9480505938 | E18: =IF(B18<>"",VLOOKUP(B18,LEADS!A:I,9,FALSE),"") -> Kanchinalu | F18: =IF(B18<>"",VLOOKUP(B18,LEADS!A:J,10,FALSE),"") -> Thirthahalli | G18: =IF(B18<>"",VLOOKUP(B18,LEADS!A:O,15,FALSE),"") -> 400 | H18: 45979 | J18: Dr. Manjunath | O18: =IF(AND(ISBLANK(Field_Visit[Visit Actual Date]),NOT(ISBLANK(Field_Visit[Visit Scheduled Date]))),"Scheduled",IF(NOT(ISBLANK(Field_Visit[Visit Actual Date])),"Visited","")) -> Scheduled
A19: =IF(B19<>"","FIE-"&TEXT(ROW()-1,"0000"),"") -> FIE-0018 | B19: LEA-0023 | C19: =IF(B19<>"",VLOOKUP(B19,LEADS!A:E,5,FALSE),"") -> Ashiq | D19: =IF(B19<>"",VLOOKUP(B19,LEADS!A:F,6,FALSE),"") -> 7899154604 | E19: =IF(B19<>"",VLOOKUP(B19,LEADS!A:I,9,FALSE),"") -> Neralakoduge | F19: =IF(B19<>"",VLOOKUP(B19,LEADS!A:J,10,FALSE),"") -> Thirthahalli | G19: =IF(B19<>"",VLOOKUP(B19,LEADS!A:O,15,FALSE),"") -> 400 | H19: 45979 | J19: Dr. Manjunath | O19: =IF(AND(ISBLANK(Field_Visit[Visit Actual Date]),NOT(ISBLANK(Field_Visit[Visit Scheduled Date]))),"Scheduled",IF(NOT(ISBLANK(Field_Visit[Visit Actual Date])),"Visited","")) -> Scheduled
A20: =IF(B20<>"","FIE-"&TEXT(ROW()-1,"0000"),"") -> FIE-0019 | B20: LEA-0024 | C20: =IF(B20<>"",VLOOKUP(B20,LEADS!A:E,5,FALSE),"") -> Rabort | D20: =IF(B20<>"",VLOOKUP(B20,LEADS!A:F,6,FALSE),"") -> 9449390925 | E20: =IF(B20<>"",VLOOKUP(B20,LEADS!A:I,9,FALSE),"") -> Kalyani Agrahara | F20: =IF(B20<>"",VLOOKUP(B20,LEADS!A:J,10,FALSE),"") -> Thirthahalli | G20: =IF(B20<>"",VLOOKUP(B20,LEADS!A:O,15,FALSE),"") -> 4000 | H20: 45979 | J20: Dr. Manjunath | O20: =IF(AND(ISBLANK(Field_Visit[Visit Actual Date]),NOT(ISBLANK(Field_Visit[Visit Scheduled Date]))),"Scheduled",IF(NOT(ISBLANK(Field_Visit[Visit Actual Date])),"Visited","")) -> Scheduled
A21: =IF(B21<>"","FIE-"&TEXT(ROW()-1,"0000"),"") -> FIE-0020 | B21: LEA-0025 | C21: =IF(B21<>"",VLOOKUP(B21,LEADS!A:E,5,FALSE),"") -> Sunil kumar | D21: =IF(B21<>"",VLOOKUP(B21,LEADS!A:F,6,FALSE),"") -> 7975242855 | E21: =IF(B21<>"",VLOOKUP(B21,LEADS!A:I,9,FALSE),"") -> Rameshwar | F21: =IF(B21<>"",VLOOKUP(B21,LEADS!A:J,10,FALSE),"") -> Savlanga | G21: =IF(B21<>"",VLOOKUP(B21,LEADS!A:O,15,FALSE),"") -> 1080 | H21: 45980 | J21: Dr. Manjunath | O21: =IF(AND(ISBLANK(Field_Visit[Visit Actual Date]),NOT(ISBLANK(Field_Visit[Visit Scheduled Date]))),"Scheduled",IF(NOT(ISBLANK(Field_Visit[Visit Actual Date])),"Visited","")) -> Scheduled
A22: =IF(B22<>"","FIE-"&TEXT(ROW()-1,"0000"),"") -> FIE-0021 | B22: LEA-0026 | C22: =IF(B22<>"",VLOOKUP(B22,LEADS!A:E,5,FALSE),"") -> Kumar Swamy | D22: =IF(B22<>"",VLOOKUP(B22,LEADS!A:F,6,FALSE),"") -> 9986771949 | E22: =IF(B22<>"",VLOOKUP(B22,LEADS!A:I,9,FALSE),"") -> Sogilu | F22: =IF(B22<>"",VLOOKUP(B22,LEADS!A:J,10,FALSE),"") -> Savlanga | G22: =IF(B22<>"",VLOOKUP(B22,LEADS!A:O,15,FALSE),"") -> 1800 | H22: 45980 | J22: Dr. Manjunath | O22: =IF(AND(ISBLANK(Field_Visit[Visit Actual Date]),NOT(ISBLANK(Field_Visit[Visit Scheduled Date]))),"Scheduled",IF(NOT(ISBLANK(Field_Visit[Visit Actual Date])),"Visited","")) -> Scheduled
A23: =IF(B23<>"","FIE-"&TEXT(ROW()-1,"0000"),"") -> FIE-0022 | B23: LEA-0027 | C23: =IF(B23<>"",VLOOKUP(B23,LEADS!A:E,5,FALSE),"") -> Nagaraj H | D23: =IF(B23<>"",VLOOKUP(B23,LEADS!A:F,6,FALSE),"") -> 8792444217 | E23: =IF(B23<>"",VLOOKUP(B23,LEADS!A:I,9,FALSE),"") -> Rameshwar | F23: =IF(B23<>"",VLOOKUP(B23,LEADS!A:J,10,FALSE),"") -> Savlanga | G23: =IF(B23<>"",VLOOKUP(B23,LEADS!A:O,15,FALSE),"") -> 450 | H23: 45980 | J23: Dr. Manjunath | O23: =IF(AND(ISBLANK(Field_Visit[Visit Actual Date]),NOT(ISBLANK(Field_Visit[Visit Scheduled Date]))),"Scheduled",IF(NOT(ISBLANK(Field_Visit[Visit Actual Date])),"Visited","")) -> Scheduled
A24: =IF(B24<>"","FIE-"&TEXT(ROW()-1,"0000"),"") -> FIE-0023 | B24: LEA-0028 | C24: =IF(B24<>"",VLOOKUP(B24,LEADS!A:E,5,FALSE),"") -> Mahesh | D24: =IF(B24<>"",VLOOKUP(B24,LEADS!A:F,6,FALSE),"") -> 9986457008 | E24: =IF(B24<>"",VLOOKUP(B24,LEADS!A:I,9,FALSE),"") -> Bikanahalli | F24: =IF(B24<>"",VLOOKUP(B24,LEADS!A:J,10,FALSE),"") -> Savlanga | G24: =IF(B24<>"",VLOOKUP(B24,LEADS!A:O,15,FALSE),"") -> 5000 | H24: 45980 | J24: Dr. Manjunath | O24: =IF(AND(ISBLANK(Field_Visit[Visit Actual Date]),NOT(ISBLANK(Field_Visit[Visit Scheduled Date]))),"Scheduled",IF(NOT(ISBLANK(Field_Visit[Visit Actual Date])),"Visited","")) -> Scheduled
... A56: =IF(B56<>"","FIE-"&TEXT(ROW()-1,"0000"),"") -> FIE-0055 | B56: LEA-0075 | C56: =IF(B56<>"",VLOOKUP(B56,LEADS!A:E,5,FALSE),"") -> Lingaraju | D56: =IF(B56<>"",VLOOKUP(B56,LEADS!A:F,6,FALSE),"") -> 9900203295 | E56: =IF(B56<>"",VLOOKUP(B56,LEADS!A:I,9,FALSE),"") -> Lakshmipura | F56: =IF(B56<>"",VLOOKUP(B56,LEADS!A:J,10,FALSE),"") -> Bhadravathi | G56: =IF(B56<>"",VLOOKUP(B56,LEADS!A:O,15,FALSE),"") -> 6000 | H56: 45992 | J56: Dr. Manjunath | O56: =IF(AND(ISBLANK(Field_Visit[Visit Actual Date]),NOT(ISBLANK(Field_Visit[Visit Scheduled Date]))),"Scheduled",IF(NOT(ISBLANK(Field_Visit[Visit Actual Date])),"Visited","")) -> Scheduled
A57: =IF(B57<>"","FIE-"&TEXT(ROW()-1,"0000"),"") -> FIE-0056 | B57: LEA-0087 | C57: =IF(B57<>"",VLOOKUP(B57,LEADS!A:E,5,FALSE),"") -> Mother Earth | D57: =IF(B57<>"",VLOOKUP(B57,LEADS!A:F,6,FALSE),"") -> 7760551112 | E57: =IF(B57<>"",VLOOKUP(B57,LEADS!A:I,9,FALSE),"") -> Jagadapura | F57: =IF(B57<>"",VLOOKUP(B57,LEADS!A:J,10,FALSE),"") -> Channappattna | G57: =IF(B57<>"",VLOOKUP(B57,LEADS!A:O,15,FALSE),"") -> 5000 | J57: Dr. Manjunath | K57: Not Interested | O57: =IF(AND(ISBLANK(Field_Visit[Visit Actual Date]),NOT(ISBLANK(Field_Visit[Visit Scheduled Date]))),"Scheduled",IF(NOT(ISBLANK(Field_Visit[Visit Actual Date])),"Visited","")) -> Scheduled
A58: =IF(B58<>"","FIE-"&TEXT(ROW()-1,"0000"),"") -> FIE-0057 | B58: LEA-0088 | C58: =IF(B58<>"",VLOOKUP(B58,LEADS!A:E,5,FALSE),"") -> Suresh K S | D58: =IF(B58<>"",VLOOKUP(B58,LEADS!A:F,6,FALSE),"") -> 8183894646 | E58: =IF(B58<>"",VLOOKUP(B58,LEADS!A:I,9,FALSE),"") -> Kalyur | F58: =IF(B58<>"",VLOOKUP(B58,LEADS!A:J,10,FALSE),"") -> T Narasipura | G58: =IF(B58<>"",VLOOKUP(B58,LEADS!A:O,15,FALSE),"") -> 5000 | H58: 45996 | J58: Dr. Manjunath | K58: Not Interested | O58: =IF(AND(ISBLANK(Field_Visit[Visit Actual Date]),NOT(ISBLANK(Field_Visit[Visit Scheduled Date]))),"Scheduled",IF(NOT(ISBLANK(Field_Visit[Visit Actual Date])),"Visited","")) -> Scheduled
A59: =IF(B59<>"","FIE-"&TEXT(ROW()-1,"0000"),"") -> FIE-0058 | B59: LEA-0093 | C59: =IF(B59<>"",VLOOKUP(B59,LEADS!A:E,5,FALSE),"") -> Imtiyaz | D59: =IF(B59<>"",VLOOKUP(B59,LEADS!A:F,6,FALSE),"") -> 7019118298 | E59: =IF(B59<>"",VLOOKUP(B59,LEADS!A:I,9,FALSE),"") -> Kammaradi | F59: =IF(B59<>"",VLOOKUP(B59,LEADS!A:J,10,FALSE),"") -> Thirthahalli | G59: =IF(B59<>"",VLOOKUP(B59,LEADS!A:O,15,FALSE),"") -> 1600 | H59: 46006 | I59: 46006 | J59: Dr. Manjunath | K59: Good Fit - Interested | M59: Yes | O59: =IF(AND(ISBLANK(Field_Visit[Visit Actual Date]),NOT(ISBLANK(Field_Visit[Visit Scheduled Date]))),"Scheduled",IF(NOT(ISBLANK(Field_Visit[Visit Actual Date])),"Visited","")) -> Visited
A60: =IF(B60<>"","FIE-"&TEXT(ROW()-1,"0000"),"") -> FIE-0059 | B60: LEA-0311 | C60: =IF(B60<>"",VLOOKUP(B60,LEADS!A:E,5,FALSE),"") -> Mohan | D60: =IF(B60<>"",VLOOKUP(B60,LEADS!A:F,6,FALSE),"") -> 9740919288 | E60: =IF(B60<>"",VLOOKUP(B60,LEADS!A:I,9,FALSE),"") -> Kuppuru | F60: =IF(B60<>"",VLOOKUP(B60,LEADS!A:J,10,FALSE),"") -> N R Pura | G60: =IF(B60<>"",VLOOKUP(B60,LEADS!A:O,15,FALSE),"") -> 2500 | H60: 46032 | I60: 46032 | K60: Good Fit - Interested | M60: Yes | O60: =IF(AND(ISBLANK(Field_Visit[Visit Actual Date]),NOT(ISBLANK(Field_Visit[Visit Scheduled Date]))),"Scheduled",IF(NOT(ISBLANK(Field_Visit[Visit Actual Date])),"Visited","")) -> Visited
A61: =IF(B61<>"","FIE-"&TEXT(ROW()-1,"0000"),"") -> FIE-0060 | B61: LEA-0390 | C61: =IF(B61<>"",VLOOKUP(B61,LEADS!A:E,5,FALSE),"") -> Girish | D61: =IF(B61<>"",VLOOKUP(B61,LEADS!A:F,6,FALSE),"") -> 9741159943 | E61: =IF(B61<>"",VLOOKUP(B61,LEADS!A:I,9,FALSE),"") -> Dugalapura | F61: =IF(B61<>"",VLOOKUP(B61,LEADS!A:J,10,FALSE),"") -> Tarikere | G61: =IF(B61<>"",VLOOKUP(B61,LEADS!A:O,15,FALSE),"") -> 9000 | H61: 46040 | I61: 46038 | J61: Dr. Manjunath | K61: Good Fit - Interested | M61: Yes | O61: =IF(AND(ISBLANK(Field_Visit[Visit Actual Date]),NOT(ISBLANK(Field_Visit[Visit Scheduled Date]))),"Scheduled",IF(NOT(ISBLANK(Field_Visit[Visit Actual Date])),"Visited","")) -> Visited
A62: =IF(B62<>"","FIE-"&TEXT(ROW()-1,"0000"),"") -> FIE-0061 | B62: LEA-0391 | C62: =IF(B62<>"",VLOOKUP(B62,LEADS!A:E,5,FALSE),"") -> Murali | D62: =IF(B62<>"",VLOOKUP(B62,LEADS!A:F,6,FALSE),"") -> 8867849048 | E62: =IF(B62<>"",VLOOKUP(B62,LEADS!A:I,9,FALSE),"") -> Dugalapura | F62: =IF(B62<>"",VLOOKUP(B62,LEADS!A:J,10,FALSE),"") -> Tarikere | G62: =IF(B62<>"",VLOOKUP(B62,LEADS!A:O,15,FALSE),"") -> 5000 | H62: 46040 | O62: =IF(AND(ISBLANK(Field_Visit[Visit Actual Date]),NOT(ISBLANK(Field_Visit[Visit Scheduled Date]))),"Scheduled",IF(NOT(ISBLANK(Field_Visit[Visit Actual Date])),"Visited","")) -> Scheduled
A63: =IF(B63<>"","FIE-"&TEXT(ROW()-1,"0000"),"") -> FIE-0062 | B63: LEA-0392 | C63: =IF(B63<>"",VLOOKUP(B63,LEADS!A:E,5,FALSE),"") -> Kumar | D63: =IF(B63<>"",VLOOKUP(B63,LEADS!A:F,6,FALSE),"") -> 9980309766 | E63: =IF(B63<>"",VLOOKUP(B63,LEADS!A:I,9,FALSE),"") -> Rangenahalli | F63: =IF(B63<>"",VLOOKUP(B63,LEADS!A:J,10,FALSE),"") -> Tarikere | G63: =IF(B63<>"",VLOOKUP(B63,LEADS!A:O,15,FALSE),"") -> 2500 | H63: 46040 | O63: =IF(AND(ISBLANK(Field_Visit[Visit Actual Date]),NOT(ISBLANK(Field_Visit[Visit Scheduled Date]))),"Scheduled",IF(NOT(ISBLANK(Field_Visit[Visit Actual Date])),"Visited","")) -> Scheduled
A64: =IF(B64<>"","FIE-"&TEXT(ROW()-1,"0000"),"") -> FIE-0063 | B64: LEA-0393 | C64: =IF(B64<>"",VLOOKUP(B64,LEADS!A:E,5,FALSE),"") -> Pradeep | D64: =IF(B64<>"",VLOOKUP(B64,LEADS!A:F,6,FALSE),"") -> 9743468228 | E64: =IF(B64<>"",VLOOKUP(B64,LEADS!A:I,9,FALSE),"") -> Rangenahalli | F64: =IF(B64<>"",VLOOKUP(B64,LEADS!A:J,10,FALSE),"") -> Tarikere | G64: =IF(B64<>"",VLOOKUP(B64,LEADS!A:O,15,FALSE),"") -> 4000 | H64: 46040 | O64: =IF(AND(ISBLANK(Field_Visit[Visit Actual Date]),NOT(ISBLANK(Field_Visit[Visit Scheduled Date]))),"Scheduled",IF(NOT(ISBLANK(Field_Visit[Visit Actual Date])),"Visited","")) -> Scheduled
A65: =IF(B65<>"","FIE-"&TEXT(ROW()-1,"0000"),"") -> FIE-0064 | B65: LEA-0394 | C65: =IF(B65<>"",VLOOKUP(B65,LEADS!A:E,5,FALSE),"") -> Ramesh | D65: =IF(B65<>"",VLOOKUP(B65,LEADS!A:F,6,FALSE),"") -> 9901880325 | E65: =IF(B65<>"",VLOOKUP(B65,LEADS!A:I,9,FALSE),"") -> Basavanahalli | F65: =IF(B65<>"",VLOOKUP(B65,LEADS!A:J,10,FALSE),"") -> Tarikere | G65: =IF(B65<>"",VLOOKUP(B65,LEADS!A:O,15,FALSE),"") -> 1300 | H65: 46040 | O65: =IF(AND(ISBLANK(Field_Visit[Visit Actual Date]),NOT(ISBLANK(Field_Visit[Visit Scheduled Date]))),"Scheduled",IF(NOT(ISBLANK(Field_Visit[Visit Actual Date])),"Visited","")) -> Scheduled
A66: =IF(B66<>"","FIE-"&TEXT(ROW()-1,"0000"),"") | C66: =IF(B66<>"",VLOOKUP(B66,LEADS!A:E,5,FALSE),"") | D66: =IF(B66<>"",VLOOKUP(B66,LEADS!A:F,6,FALSE),"") | E66: =IF(B66<>"",VLOOKUP(B66,LEADS!A:I,9,FALSE),"") | F66: =IF(B66<>"",VLOOKUP(B66,LEADS!A:J,10,FALSE),"") | G66: =IF(B66<>"",VLOOKUP(B66,LEADS!A:O,15,FALSE),"") | O66: =IF(AND(ISBLANK(Field_Visit[Visit Actual Date]),NOT(ISBLANK(Field_Visit[Visit Scheduled Date]))),"Scheduled",IF(NOT(ISBLANK(Field_Visit[Visit Actual Date])),"Visited",""))
A67: =IF(B67<>"","FIE-"&TEXT(ROW()-1,"0000"),"") | C67: =IF(B67<>"",VLOOKUP(B67,LEADS!A:E,5,FALSE),"") | D67: =IF(B67<>"",VLOOKUP(B67,LEADS!A:F,6,FALSE),"") | E67: =IF(B67<>"",VLOOKUP(B67,LEADS!A:I,9,FALSE),"") | F67: =IF(B67<>"",VLOOKUP(B67,LEADS!A:J,10,FALSE),"") | G67: =IF(B67<>"",VLOOKUP(B67,LEADS!A:O,15,FALSE),"") | O67: =IF(AND(ISBLANK(Field_Visit[Visit Actual Date]),NOT(ISBLANK(Field_Visit[Visit Scheduled Date]))),"Scheduled",IF(NOT(ISBLANK(Field_Visit[Visit Actual Date])),"Visited",""))
A68: =IF(B68<>"","FIE-"&TEXT(ROW()-1,"0000"),"") | C68: =IF(B68<>"",VLOOKUP(B68,LEADS!A:E,5,FALSE),"") | D68: =IF(B68<>"",VLOOKUP(B68,LEADS!A:F,6,FALSE),"") | E68: =IF(B68<>"",VLOOKUP(B68,LEADS!A:I,9,FALSE),"") | F68: =IF(B68<>"",VLOOKUP(B68,LEADS!A:J,10,FALSE),"") | G68: =IF(B68<>"",VLOOKUP(B68,LEADS!A:O,15,FALSE),"") | O68: =IF(AND(ISBLANK(Field_Visit[Visit Actual Date]),NOT(ISBLANK(Field_Visit[Visit Scheduled Date]))),"Scheduled",IF(NOT(ISBLANK(Field_Visit[Visit Actual Date])),"Visited",""))
A69: =IF(B69<>"","FIE-"&TEXT(ROW()-1,"0000"),"") | C69: =IF(B69<>"",VLOOKUP(B69,LEADS!A:E,5,FALSE),"") | D69: =IF(B69<>"",VLOOKUP(B69,LEADS!A:F,6,FALSE),"") | E69: =IF(B69<>"",VLOOKUP(B69,LEADS!A:I,9,FALSE),"") | F69: =IF(B69<>"",VLOOKUP(B69,LEADS!A:J,10,FALSE),"") | G69: =IF(B69<>"",VLOOKUP(B69,LEADS!A:O,15,FALSE),"") | O69: =IF(AND(ISBLANK(Field_Visit[Visit Actual Date]),NOT(ISBLANK(Field_Visit[Visit Scheduled Date]))),"Scheduled",IF(NOT(ISBLANK(Field_Visit[Visit Actual Date])),"Visited",""))
A70: =IF(B70<>"","FIE-"&TEXT(ROW()-1,"0000"),"") | C70: =IF(B70<>"",VLOOKUP(B70,LEADS!A:E,5,FALSE),"") | D70: =IF(B70<>"",VLOOKUP(B70,LEADS!A:F,6,FALSE),"") | E70: =IF(B70<>"",VLOOKUP(B70,LEADS!A:I,9,FALSE),"") | F70: =IF(B70<>"",VLOOKUP(B70,LEADS!A:J,10,FALSE),"") | G70: =IF(B70<>"",VLOOKUP(B70,LEADS!A:O,15,FALSE),"") | O70: =IF(AND(ISBLANK(Field_Visit[Visit Actual Date]),NOT(ISBLANK(Field_Visit[Visit Scheduled Date]))),"Scheduled",IF(NOT(ISBLANK(Field_Visit[Visit Actual Date])),"Visited",""))
A71: =IF(B71<>"","FIE-"&TEXT(ROW()-1,"0000"),"") | C71: =IF(B71<>"",VLOOKUP(B71,LEADS!A:E,5,FALSE),"") | D71: =IF(B71<>"",VLOOKUP(B71,LEADS!A:F,6,FALSE),"") | E71: =IF(B71<>"",VLOOKUP(B71,LEADS!A:I,9,FALSE),"") | F71: =IF(B71<>"",VLOOKUP(B71,LEADS!A:J,10,FALSE),"") | G71: =IF(B71<>"",VLOOKUP(B71,LEADS!A:O,15,FALSE),"") | O71: =IF(AND(ISBLANK(Field_Visit[Visit Actual Date]),NOT(ISBLANK(Field_Visit[Visit Scheduled Date]))),"Scheduled",IF(NOT(ISBLANK(Field_Visit[Visit Actual Date])),"Visited",""))
...

Sheet QUOTATIONS & DEALS
A1: Qoute ID | B1: Visit ID | C1: Lead Id | D1: Farmer Name | E1: Quotation Date | F1: Quotation Amount | G1: Prepared By | H1: Deal status | I1: Close date | J1: Final sale Amount | K1: Payment status | L1: Advance Amount | M1: Advance date | N1: Balance Amount | O1: Final Payment date | P1: Reason Lost | Q1: Notes | R1: Last Updated
A2: =IF(B2<>"","QUO-"&TEXT(ROW()-1,"0000"),"") -> QUO-0001 | B2: FIE-0001 | C2: =IF(B2<>"",VLOOKUP(B2,'FIELD VISITS'!A:B,2,FALSE),"") -> LEA-0001 | D2: =IF(B2<>"",VLOOKUP(B2,'FIELD VISITS'!A:C,3,FALSE),"") -> Natesh | E2: 45958 | F2: 230000 | G2: Keerthi M J | H2: Sent | I2: 45958 | J2: 230000 | K2: Received | R2: =IF(E2<>"",TODAY(),"") -> 46039
A3: =IF(B3<>"","QUO-"&TEXT(ROW()-1,"0000"),"") -> QUO-0002 | B3: FIE-0002 | C3: =IF(B3<>"",VLOOKUP(B3,'FIELD VISITS'!A:B,2,FALSE),"") -> LEA-0003 | D3: =IF(B3<>"",VLOOKUP(B3,'FIELD VISITS'!A:C,3,FALSE),"") -> Dr Srinivas | E3: 45955 | F3: 121080 | G3: Gowthami | H3: Order Delivered | I3: 45955 | J3: 121080 | K3: Received | Q3: Orderd delivered | R3: =IF(E3<>"",TODAY(),"") -> 46039
A4: =IF(B4<>"","QUO-"&TEXT(ROW()-1,"0000"),"") -> QUO-0003 | B4: FIE-0003 | C4: =IF(B4<>"",VLOOKUP(B4,'FIELD VISITS'!A:B,2,FALSE),"") -> LEA-0002 | D4: =IF(B4<>"",VLOOKUP(B4,'FIELD VISITS'!A:C,3,FALSE),"") -> Asha Rani | E4: 45934 | F4: 167010 | G4: Gowthami | H4: In Discussion | I4: 45954 | Q4: Orderd Nov First Week | R4: =IF(E4<>"",TODAY(),"") -> 46039
A5: =IF(B5<>"","QUO-"&TEXT(ROW()-1,"0000"),"") -> QUO-0004 | B5: FIE-0004 | C5: =IF(B5<>"",VLOOKUP(B5,'FIELD VISITS'!A:B,2,FALSE),"") -> LEA-0004 | D5: =IF(B5<>"",VLOOKUP(B5,'FIELD VISITS'!A:C,3,FALSE),"") -> Imran Syed Chand | E5: 45930 | F5: 312800 | G5: Gowthami | H5: In Discussion | R5: =IF(E5<>"",TODAY(),"") -> 46039
A6: =IF(B6<>"","QUO-"&TEXT(ROW()-1,"0000"),"") -> QUO-0005 | B6: FIE-0058 | C6: =IF(B6<>"",VLOOKUP(B6,'FIELD VISITS'!A:B,2,FALSE),"") -> LEA-0093 | D6: =IF(B6<>"",VLOOKUP(B6,'FIELD VISITS'!A:C,3,FALSE),"") -> Imtiyaz | E6: 46006 | F6: 82360 | G6: Gowthami | H6: Order Delivered | I6: 46016 | J6: 82360 | K6: Partial | N6: 2360 | R6: =IF(E6<>"",TODAY(),"") -> 46039
A7: =IF(B7<>"","QUO-"&TEXT(ROW()-1,"0000"),"") -> QUO-0006 | B7: FIE-0060 | C7: =IF(B7<>"",VLOOKUP(B7,'FIELD VISITS'!A:B,2,FALSE),"") -> LEA-0390 | R7: =IF(E7<>"",TODAY(),"")
A8: =IF(B8<>"","QUO-"&TEXT(ROW()-1,"0000"),"") | D8: =IF(B8<>"",VLOOKUP(B8,LEADS!A:D,5,FALSE),"") | N8: =IF(AND(F8<>"",L8<>""),F8-L8,"") | R8: =IF(B8<>"",TODAY(),"")

Sheet DASHBOARD
